Workbook
Name SlicerCache_Table_1_Col_1: #N/A
Name SlicerCache_Table_3_Col_10: #N/A
Name SlicerCache_Table_4_Col_10: #N/A
Name SlicerCache_Table_5_Col_10: #N/A

Sheet Resumen
A1: CC | B1: Ppto | C1: Ppto ajustado | D1: ppto doc. | E1: Saldo | F1: % | H1: KELLUN | I1: CON TRASPASO | J1: DIFERENCIA | K1: 46149
A2: 409-1722 REMODELACIONES-OBRAS | B2: =SUMIF('Ppto 2026'!$D:$D,A2,'Ppto 2026'!$O:$O) -> 730355177 | C2: 822951860 | D2: =SUMIF('Ppto 2026'!$D:$D,A2,'Ppto 2026'!$P:$P) -> 576590671 | E2: =C2-D2 -> 246361189 | F2: =D2/B2 -> 0.78946612 | H2: 264211915 | I2: =H2+B37 -> 264211915 | J2: =I2-E2 -> 17850726 | K2: =(J2/E2) -> 0.072457541
A3: 409-5243 INSTITUTO TECNOLOGICO | B3: =SUMIF('Ppto 2026'!$D:$D,A3,'Ppto 2026'!$O:$O) -> 1641182758 | C3: ='Ppto 2026'!O11 -> 1641182758 | D3: =SUMIF('Ppto 2026'!$D:$D,A3,'Ppto 2026'!$P:$P) -> 1577697306 | E3: =C3-D3 -> 63485452 | F3: =D3/B3 -> 0.96131726 | H3: 60488457 | I3: =B45+H3 -> 60488457 | J3: =I3-E3 -> -2996995 | K3: =(J3/E3) -> -0.047207587
A4: 409-5503 PROYECTO TÚNEL SALIDA Y CALLE PROLONGACIÓN CJPII | B4: =SUMIF('Ppto 2026'!$D:$D,A4,'Ppto 2026'!$O:$O) -> 0 | D4: =SUMIF('Ppto 2026'!$D:$D,A4,'Ppto 2026'!$P:$P) -> 0 | E4: =C4-D4 -> 0 | F4: =D4/B4 -> #DIV/0! | J4: =H4-E4 -> 0 | K4: =(J4/E4) -> #DIV/0!
A5: 409-5506 - CASINO VRAE | B5: =SUMIF('Ppto 2026'!$D:$D,A5,'Ppto 2026'!$O:$O) -> 995200912 | C5: 995200912 | D5: =SUMIF('Ppto 2026'!$D:$D,A5,'Ppto 2026'!$P:$P) -> 957708957 | E5: =C5-D5 -> 37491955 | F5: =D5/B5 -> 0.96232725 | H5: 133118933 | I5: =B53+H5 -> 133118933 | J5: =H5-E5 -> 95626978 | K5: =(J5/E5) -> 2.5505999
A6: 409-6293 - CENTRO RECREACIONAL SAN NICOLAS | B6: 40000000 | C6: =B6 -> 40000000 | D6: =SUMIF('Ppto 2026'!$D:$D,A6,'Ppto 2026'!$P:$P) -> 2196742 | E6: =C6-D6 -> 37803258 | H6: $ 40.000.000
I8: =C5+C3+C2 -> 3459335530 | J8: =I8*0.05 -> 1.7296678e+08
A35: Regularización gastos
A37: 409-1722-REMODELACIONES-OBRAS
A38: Detalle | B38: Monto | D38: Obs. | E38: Estado
A39: SP:11753 - OC:10964 - FCAEL. 74427 - MELMAN SPA | B39: 47267344 | D39: Ppto. 2025 | E39: TRUE
A45: 409-5243 INSTITUTO TECNOLOGICO
A46: Detalle | B46: Monto | D46: Obs. | E46: Estado
A47: SP:9942 - OC:9031 - FCAEL. 499 - LUIS SAEZ ALLENDE | B47: 110752237 | D47: Ppto. 2025 | E47: TRUE
A53: 409-5506 - CASINO VRAE | B53: =B55+B56+B57 -> 0
A54: Detalle | B54: Monto | D54: Obs. | E54: Estado
E55: FALSE

Sheet Proyección
L1: =L2/'Ppto 2026'!$P$3 -> 0.00055517045 | M1: =M2/'Ppto 2026'!$P$3 -> 0.0016306529 | N1: =N2/'Ppto 2026'!$P$3 -> 0.012649957 | O1: =O2/'Ppto 2026'!$P$3 -> 0.015109029 | P1: =P2/'Ppto 2026'!$P$3 -> 0.00064107442 | Q1: =Q2/'Ppto 2026'!$P$3 -> 0 | R1: =R2/'Ppto 2026'!$P$3 -> 0 | S1: =S2/'Ppto 2026'!$P$3 -> 0.0012674041 | ... BM1: =BM2/'Ppto 2026'!$P$3 -> 0
L2: =SUM(L5:L79) -> 1905200 | M2: =SUM(M5:M79) -> 5595975 | N2: =SUM(N5:N79) -> 43411350 | O2: =SUM(O5:O79) -> 51850242 | P2: =SUM(P5:P79) -> 2200000 | Q2: =SUM(Q5:Q79) -> 0 | R2: =SUM(R5:R79) -> 0 | S2: =SUM(S5:S79) -> 4349400 | ... BM2: =SUM(BM5:BM79) -> 0
L3: Semana 1-Ene | M3: Semana 2-Enero | N3: Semana 3-Ene | O3: Semana 4-Ene | P3: Semana 1-Feb | Q3: Semana 2-Feb | R3: Semana 3-Febr | S3: Semana 4-Feb | T3: Semana 1-Mar | U3: Semana 2-Marz | V3: Semana 3-Marzo | W3: Semana 4-Mar | X3: Semana 1-Abri | Y3: Semana 2-Abri | Z3: Semana 3-Abril | AA3: Semana 4-Abril | AB3: Semana 5-Abri | AC3: Semana 1-May | AD3: Semana 2-Mayo | AE3: Semana 3-Mayo | AF3: Semana 4-Mayo | AG3: Semana 1-Jun | AH3: Semana 2-Jun | AI3: Semana 3-Junio | AJ3: Semana 4-Junio | AK3: Semana 1-Juli | AL3: Semana 2-Jul | AM3: Semana 3-Julio | AN3: Semana 4-Julio | AO3: Semana 5-Juli | AP3: Semana 1-Ago | AQ3: Semana 2-Agos | AR3: Semana 3-Agos | AS3: Semana 4-Agos | AT3: Semana 1-Sept | AU3: Semana 2-Septi | AV3: Semana 3-Septi | AW3: Semana 4-Septi | AX3: Semana 5-Septi | AY3: Semana 1-Octu | AZ3: Semana 2-Oct | BA3: Semana 3-Octu | BB3: Semana 4-Octu | BC3: Semana 5-Octu | BD3: Semana 1-Nov | BE3: Semana 2-Novi | BF3: Semana 3-Novi | BG3: Semana 4-Novi | BH3: Semana 1-Dic | BI3: Semana 2-Dic | BJ3: Semana 3-Dici | BK3: Semana 4-Dici | BL3: Semana 5-Dici | BM3: Semana 1-Ene
A4: CC | B4: Año | C4: OP | D4: OC | E4: Descripción | F4: Monto | G4: Pagado | H4: Saldo | I4: Columna 1 | J4: Columna 2 | K4: Δ | L4: 05 al 11 | M4: 12 al 18 | N4: 19 al 25 | O4: 26 al 01 | P4: 02 al 08 | Q4: 09 al 15 | R4: 16 al 22 | S4: 23 al 01 | T4: 02 al 08 2 | U4: 09 al 15 2 | V4: 16 al 22 2 | W4: 23 al 29 | X4: 30 al 05 | Y4: 06 al 12 | Z4: 13 al 19 | AA4: 20 al 26 | AB4: 27 al 03 | AC4: 04 al 10 | AD4: 11 al 17 | AE4: 18 al 24 | AF4: 25 al 31 | AG4: 01 al 07 | AH4: 08 al 14 | AI4: 15 al 21 | AJ4: 22 al 28 | AK4: 29 al 05 | AL4: 06 al 12 2 | AM4: 13 al 19 2 | AN4: 20 al 26 2 | AO4: 27 al 02 | AP4: 03 al 09 | AQ4: 10 al 16 | AR4: 17 al 23 | AS4: 24 al 30 | AT4: 31al 06 | AU4: 07 al 13 | AV4: 14 al 20 | AW4: 21 al 27 | AX4: 28 al 04 | AY4: 05 al 11 2 | AZ4: 12 al 18 2 | BA4: 19 al 25 2 | BB4: 26 al 01 2 | BC4: 02 al 08 3 | BD4: 09 al 15 3 | BE4: 16 al 22 3 | BF4: 23 al 29 2 | BG4: 24 al 30 2 | BH4: 30 al 06 | BI4: 07 al 13 2 | BJ4: 14 al 20 2 | BK4: 21 al 27 2 | BL4: 28 al 03 | BM4: 05 al 11 3
A5: 409-5243 INSTITUTO TECNOLOGICO | B5: 2024 | D5: 8022 | E5: Edificio Ingeniería (ex TEC) | F5: 4408299870 | G5: =200000000+214576722+451540786+242312734+224174189+155623352+252294712+201102519+155455601+218152853+324983774+366374243+153086824+152511772+102298014+203742698+184685827+170139342 -> 3973055962 | H5: =F5-G5 -> 435243908 | I5: LSA INGENIERIA Y CONSTRUCCIÓN E.I.R.L. | J5: J.Solis de Ovando | K5: =F5-G5-(SUM(L5:BM5)) -> 0 | T5: 185222684 | AC5: 250021224
A6: 409-5243 INSTITUTO TECNOLOGICO | B6: 2025 | D6: 9031 | E6: AO N°1 Edificio Ingeniería (ex TEC) | F6: 456637235 | G6: =81204459+170270732+89858090+110752237 -> 452085518 | H6: =F6-G6 -> 4551717 | I6: LSA INGENIERIA Y CONSTRUCCIÓN E.I.R.L. | J6: J.Solis de Ovando | K6: =F6-G6-(SUM(L6:BM6)) -> 0 | AD6: 4551717
A7: 409-5243 INSTITUTO TECNOLOGICO | B7: 2024 | D7: 4075 | E7: Arquitectura Edificio Ingeniería (ex TEC) | F7: 86080359 | G7: =24432144+7173363+12912054+7173363 -> 51690924 | H7: =F7-G7 -> 34389435 | I7: SOCIEDAD DE PROFESIONALES BAIXAS Y DEL RIO ARQUITECTOS LIMITADA | J7: J.Solis de Ovando | K7: =F7-G7-(SUM(L7:BM7)) -> 14304018 | AA7: 7173363 | AF7: 8608036.1 | AJ7: 4304018
A8: 409-5243 INSTITUTO TECNOLOGICO | B8: 2025 | D8: 13112 | E8: Armado muebles Edificio de Ingenieria UCT (exTEC) | F8: 13917050 | G8: 5566820 | H8: =F8-G8 -> 8350230 | I8: ESPACIO MUEBLES LIMITADA | J8: J.Solis de Ovando | K8: =F8-G8-(SUM(L8:BM8)) -> 0 | O8: 5566820 | AD8: 2783410
A9: 409-5243 INSTITUTO TECNOLOGICO | B9: 2025 | D9: 13810 | E9: ccess point y switch Edificio de Ingenieria UCT (exTEC) | F9: 85398978 | H9: =F9-G9 -> 85398978 | J9: M.Zurita | K9: =F9-G9-(SUM(L9:BM9)) -> 85398978
A10: 409-5243 INSTITUTO TECNOLOGICO | B10: 2026 | C10: 91 | D10: 66 | E10: AUMENTO DE OBRA OC. 9031 CONSTRUCCION EDIFICIO INGENIERIA CRC (EX TEC) JUAN IGNACIO SOLIS DE OVANDO | F10: 664691208 | G10: =186646382+118263881+132505939 -> 437416202 | H10: =F10-G10 -> 227275006 | I10: LSA INGENIERIA Y CONSTRUCCIÓN E.I.R.L. | J10: J.Solis de Ovando | K10: =F10-G10-(SUM(L10:BM10)) -> 18000001 | T10: 209275005
A11: 409-5243 INSTITUTO TECNOLOGICO | B11: 2026 | C11: 699 | D11: 703 | E11: INSTALACIÓN DE ACCESS POINT EN EDIFICIO EX TEC (MAURICIO ZURITA) | F11: 2416890 | H11: =F11-G11 -> 2416890 | I11: GYG SERVICIOS | J11: M.Zurita | K11: =F11-G11-(SUM(L11:BM11)) -> 0 | X11: 2416890
A12: 409-5243 INSTITUTO TECNOLOGICO | B12: 2026 | C12: 799 | D12: 864 | E12: SOPORTES PARA INSTALACION DE TELEVISORES SALAS DE REUNIONES, SALAS DE CLASES Y LABORARIOS NUEVO EDIFICIO INGENIERIA (ARTURO MEZA) | F12: 5537070 | H12: =F12-G12 -> 5537070 | I12: GYG SERVICIOS | J12: A. Meza | K12: =F12-G12-(SUM(L12:BM12)) -> 0 | Z12: 5537070
A13: 409-5243 INSTITUTO TECNOLOGICO | B13: 2026 | C13: 788 | D13: 731 | E13: HABILITACION MOBILIARIO OFICINAS 3ER NIVEL EDIFICIO INGENIERIA CRC10 (JUAN IGNACIO SOLIS) | F13: 25523715 | H13: =F13-G13 -> 25523715 | I13: ESPACIO MUEBLES LIMITADA | J13: J.Solis de Ovando | K13: =F13-G13-(SUM(L13:BM13)) -> 1.5 | O13: 7657114.5 | T13: 17866599
A14: 409-5243 INSTITUTO TECNOLOGICO | B14: 2026 | C14: 789 | D14: 732 | E14: MUEBLES HABILITACION LABORATORIO DE COMPUTACION EDIFICIO INGENIERIA CRC10 (JUAN IGNACIO SOLIS) | F14: 8425200 | H14: =F14-G14 -> 8425200 | I14: ESPACIO MUEBLES LIMITADA | J14: J.Solis de Ovando | K14: =F14-G14-(SUM(L14:BM14)) -> 0 | O14: 2527560 | U14: 5897640
A15: 409-5243 INSTITUTO TECNOLOGICO | B15: 2026 | C15: 1473 | D15: 1578 | E15: RACK PARA DATA CENTER NUEVO EDIFICIO FACULTAD DE INGENIERIA (ARTURO MEZA)PROVEEDOR ADJUDICADO CUMPLE CON TODAS LAS ESPECIFICACIONES TECNICAS. | F15: 3704470 | H15: =F15-G15 -> 3704470 | I15: GYG SERVICIOS | J15: A. Meza | K15: =F15-G15-(SUM(L15:BM15)) -> 0 | W15: 3704470
A16: 409-5243 INSTITUTO TECNOLOGICO | B16: 2026 | C16: 1770 | D16: 1786 | E16: TELEVISORES PARA SALAS DE CLASES, REUNIONES Y LABORATORIOS NUEVO EDIFICIO INGENIERIA (ARTURO MEZA) | F16: 17043200 | H16: =F16-G16 -> 17043200 | I16: GYG SERVICIOS | J16: A. Meza | K16: =F16-G16-(SUM(L16:BM16)) -> 0 | X16: 17043200
A17: 409-5243 INSTITUTO TECNOLOGICO | B17: 2026 | C17: 1803 | D17: 1788 | E17: MOBILITARIO INTERIOR CLOSET ESCALA CON CERRADURA PISOS 1,2,3 ED. INGENIERIA CRC10 (JUAN IGNACION SOLIS) | F17: 856800 | H17: =F17-G17 -> 856800 | I17: ESPACIO MUEBLES LIMITADA | J17: J.Solis de Ovando | K17: =F17-G17-(SUM(L17:BM17)) -> 0 | AA17: 856800
A18: 409-5243 INSTITUTO TECNOLOGICO | B18: 2026 | C18: 2055 | D18: 1991 | E18: PIZARRAS MOVIL, HABILITACION SALA DE ESTUDIOS EDIFICIO INGENIERIA CRC10 (JUAN IGNACION SOLIS) | F18: 1266755 | H18: =F18-G18 -> 1266755 | I18: MELMAN SPA | J18: J.Solis de Ovando | K18: =F18-G18-(SUM(L18:BM18)) -> 0 | AB18: 1266755
A19: 409-5243 INSTITUTO TECNOLOGICO | B19: 2026 | E19: Otros | F19: 17459520 | H19: =F19-G19 -> 17459520 | K19: =F19-G19-(SUM(L19:BM19)) -> 17459520
A20: 409-5243 INSTITUTO TECNOLOGICO | B20: 2026 | C20: 2071 | D20: 2025 | E20: EMPAVONADO DE OFICINAS Y CASINO EDIFICIO CRC10 (JUAN IGNACIOS SOLIS) | F20: 3599892 | H20: =F20-G20 -> 3599892 | J20: J.Solis de Ovando | K20: =F20-G20-(SUM(L20:BM20)) -> 0 | AA20: 3599892
A21: 409-5243 INSTITUTO TECNOLOGICO | B21: 2026 | C21: 2497 | D21: 2421 | E21: MODIFICACION DE ENCHUFES Y HDMI PARA INSTALACION DE TV EN SALAS DE CLASES EDIFICIO FAC. DE INGENIERIA (ARTURO MEZA) | F21: 799442 | H21: =F21-G21 -> 799442 | I21: GYG SERVICIOS | J21: A. Meza | K21: =F21-G21-(SUM(L21:BM21)) -> 0 | AA21: 799442
A22: 409-5243 INSTITUTO TECNOLOGICO | B22: 2026 | C22: 2714 | D22: 2483 | E22: GRUPO ELECTROGENO EDIFICIO CRC10 FACULTAD DE INGENIERIA (ARTURO MEZA) | F22: 15170428 | H22: =F22-G22 -> 15170428 | I22: ELECTROPOWER | J22: A. Meza | K22: =F22-G22-(SUM(L22:BM22)) -> 0 | AD22: 15170428
A23: 409-5243 INSTITUTO TECNOLOGICO | B23: 2026 | C23: 2809 | E23: HABILITACION MOBILIARIO LABORATORIO DE PRE Y POST GRADO FACULTAD DE INGENIERIA (JUAN IGNACION SOLIS) | F23: 28468370 | H23: =F23-G23 -> 28468370 | I23: ESPACIO MUEBLES LIMITADA | J23: J.Solis de Ovando | K23: =F23-G23-(SUM(L23:BM23)) -> 0 | AA23: 8540511 | AE23: 19927859
A24: 409-5243 INSTITUTO TECNOLOGICO | B24: 2026 | C24: 208 | D24: 1940 | E24: FCAEL. 4621 - ROXANA ELIANA RI | F24: 1796409 | H24: =F24-G24 -> 1796409 | K24: =F24-G24-(SUM(L24:BM24)) -> 0 | W24: 1796409
A25: 409-5243 INSTITUTO TECNOLOGICO | B25: 2026 | E25: PAGO PERMISO EDIFICACION | F25: 10000000 | H25: =F25-G25 -> 10000000 | K25: =F25-G25-(SUM(L25:BM25)) -> 0 | AC25: 10000000
A26: 409-5243 INSTITUTO TECNOLOGICO | B26: 2026 | E26: DEA Y EXTINTORES | F26: =2019430+1302683 -> 3322113 | H26: =F26-G26 -> 3322113 | K26: =F26-G26-(SUM(L26:BM26)) -> 0 | AD26: =2019430+1302683 -> 3322113
A27: 409-5243 INSTITUTO TECNOLOGICO | B27: 2026 | E27: AUMENTO DE OBRA N3 | F27: 110000000 | H27: =F27-G27 -> 110000000 | K27: =F27-G27-(SUM(L27:BM27)) -> 0 | AC27: 110000000
A28: 409-5243 INSTITUTO TECNOLOGICO | B28: 2026 | E28: TRABAJOS VIALES POR IMIV | F28: 30000000 | H28: =F28-G28 -> 30000000 | K28: =F28-G28-(SUM(L28:BM28)) -> 0 | AG28: 30000000
A29: 409-5243 INSTITUTO TECNOLOGICO | B29: 2026 | E29: BODEGA RESPEL Y SUSPEL | F29: 15000000 | H29: =F29-G29 -> 15000000 | K29: =F29-G29-(SUM(L29:BM29)) -> 0 | AG29: 15000000
A30: 409-5243 INSTITUTO TECNOLOGICO | B30: 2026 | E30: MUEBLES PENDIENTES SALAS, OFICINAS Y AUDITORIOS | F30: 7500000 | H30: =F30-G30 -> 7500000 | K30: =F30-G30-(SUM(L30:BM30)) -> 0 | AG30: 7500000
A31: 409-5243 INSTITUTO TECNOLOGICO | B31: 2026 | E31: SEÑALETICA CENTRO RECREACIONAL CURACAUTIN (DAVID SILVA) | F31: 12000000 | H31: =F31-G31 -> 12000000 | K31: =F31-G31-(SUM(L31:BM31)) -> 0 | AC31: 12000000
A32: 409-5243 INSTITUTO TECNOLOGICO | B32: 2026 | E32: REVISORA DE ARQUITECTURA POR MP PROYECTO | F32: 4000000 | H32: =F32-G32 -> 4000000 | K32: =F32-G32-(SUM(L32:BM32)) -> 0 | AP32: 4000000
A33: 409-1722 REMODELACIONES-OBRAS | B33: 2025 | D33: 3946 | E33: Cabañas Curacautín | F33: 316857372 | G33: =95057212+27725020+27725020+75253626+75253626 -> 301014504 | H33: =F33-G33 -> 15842868 | I33: CONSTRUCTORA RUKATAMI | J33: D.Silva | K33: =F33-G33-(SUM(L33:BM33)) -> -15842869 | AA33: 15842869 | BH33: 15842869
A34: 409-1722 REMODELACIONES-OBRAS | B34: 2025 | D34: 7844 | E34: Regularización PE cjp07/cjp10/cjp104 | F34: 10833477 | G34: 2540943 | H34: =F34-G34 -> 8292534 | J34: C.Correa | K34: =F34-G34-(SUM(L34:BM34)) -> 0 | AF34: 4146267 | AO34: 4146267
A35: 409-1722 REMODELACIONES-OBRAS | B35: 2025 | D35: 10964 | E35: Mobiliario Biblioteca CSF02 etapa 2 y 3 | F35: 67524777 | G35: 20257433 | H35: =F35-G35 -> 47267344 | J35: L. Rios | K35: =F35-G35-(SUM(L35:BM35)) -> 0.1 | Z35: 47267344
A36: 409-1722 REMODELACIONES-OBRAS | B36: 2025 | D36: 11875 | E36: Remodelación Dirección General Estudiantil CSF | F36: 24367129 | G36: =7310138+7421966 -> 14732104 | H36: =F36-G36 -> 9635025 | I36: CONSTRUCTORA INGETRAPP | J36: J.Solis de Ovando | K36: =F36-G36-(SUM(L36:BM36)) -> 0 | O36: 9635025
A37: 409-1722 REMODELACIONES-OBRAS | B37: 2025 | D37: 13310 | E37: Cortinas Cabañas Curacautín | F37: 4760000 | G37: =4760000*0.3 -> 1428000 | H37: =F37-G37 -> 3332000 | J37: F.Anselme | K37: =F37-G37-(SUM(L37:BM37)) -> 0 | O37: 3332000
A38: 409-1722 REMODELACIONES-OBRAS | B38: 2025 | D38: 10880 | E38: Calculo Casino CRC | F38: 2808400 | H38: =F38-G38 -> 2808400 | J38: J.Solis de Ovando | K38: =F38-G38-(SUM(L38:BM38)) -> 0 | U38: 2808400
A39: 409-1722 REMODELACIONES-OBRAS | B39: 2025 | D39: 10877 | E39: Proyecto sanitario, pavimentación y topografía casino | F39: 2380000 | H39: =F39-G39 -> 2380000 | J39: J.Solis de Ovando | K39: =F39-G39-(SUM(L39:BM39)) -> 0 | U39: 2380000
A40: 409-1722 REMODELACIONES-OBRAS | B40: 2025 | D40: 12560 | E40: Diseño proyecto sanitario edificio Pabellón Docente | F40: 1880200 | H40: =F40-G40 -> 1880200 | J40: C.Correa | K40: =F40-G40-(SUM(L40:BM40)) -> 0 | AB40: 1880200
...

Sheet Ppto 2026
C1: UNIVERSIDAD CATÓLICA DE TEMUCO | G1: Código: SGC PS-FOR-DGDC 0005 Versión: 02 Fecha de vigencia: 12/12/2024 Página: 1 de 1 | P1: =P3-P2 -> -27596683 | T1: =T2-T3 -> 296639056 | AE1: =AE2+AE3+AE4+AE5+AE6+AE7+AE8+AE9+AE11+AE13+AE14 -> 23
C2: PRESUPUESTO INFRAESTRUCTURA 2026 | O2: Resumen | P2: =Resumen!C5+Resumen!C3+Resumen!C2 -> 3459335530 | T2: 3728377903 | W2: Continuidad de obras 2026 | Y2: Obras 2026 | AA2: Remodelaciones 2026 | AD2: D.Silva | AE2: =COUNTIFS(B:B,AD2,J:J,$W$3) -> 4
O3: 1 | P3: =X3+Z3+AB3 -> 3431738847 | R3: =SUM(R10:R84) -> 67596683 | T3: =X3+Z3+AB3 -> 3431738847 | W3: 1 | X3: =SUMIFS(Continuidad_de_obras_2026[Ppto 2026],Continuidad_de_obras_2026[Prioridad],W3) -> 2636383670 | Y3: 1 | Z3: =SUMIFS(_Obras_2026[Ppto 2026],_Obras_2026[Prioridad],Y3) -> 80000000 | AA3: 1 | AB3: =SUMIFS(Remodelaciones_2026[Ppto 2026],Remodelaciones_2026[Prioridad],AA3) -> 715355177 | AD3: M.Zurita | AE3: =COUNTIFS(B:B,AD3,J:J,$W$3) -> 1
O4: 2 | P4: =X4+Z4+AB4 -> 3467510200 | T4: =X4+Z4+AB4 -> 3467510200 | W4: 2 | X4: =SUMIFS(Continuidad_de_obras_2026[Ppto 2026],Continuidad_de_obras_2026[Prioridad],W4) -> 360000000 | Y4: 2 | Z4: =SUMIFS(_Obras_2026[Ppto 2026],_Obras_2026[Prioridad],Y4) -> 751500000 | AA4: 2 | AB4: =SUMIFS(Remodelaciones_2026[Ppto 2026],Remodelaciones_2026[Prioridad],AA4) -> 2356010200 | AD4: F.Anselme | AE4: =COUNTIFS(B:B,AD4,J:J,$W$3) -> 5
O5: 3 | P5: =X5+Z5+AB5 -> 110000000 | T5: =X5+Z5+AB5 -> 110000000 | W5: 3 | X5: =SUMIFS(Continuidad_de_obras_2026[Ppto 2026],Continuidad_de_obras_2026[Prioridad],W5) -> 0 | Y5: 3 | Z5: =SUMIFS(_Obras_2026[Ppto 2026],_Obras_2026[Prioridad],Y5) -> 0 | AA5: 3 | AB5: =SUMIFS(Remodelaciones_2026[Ppto 2026],Remodelaciones_2026[Prioridad],AA5) -> 110000000 | AD5: C.Correa | AE5: =COUNTIFS(B:B,AD5,J:J,$W$3) -> 4
T6: =O8+O20+O34 -> 7009249047 | AD6: M.Matus | AE6: =COUNTIFS(B:B,AD6,J:J,$W$3) -> 0
O7: =O8+O20+O34 -> 7009249047 | AD7: J.Solis de Ovando | AE7: =COUNTIFS(B:B,AD7,J:J,$W$3) -> 4
O8: =SUM(Continuidad_de_obras_2026[Ppto 2026]) -> 2996383670 | AD8: L. Rios | AE8: =COUNTIFS(B:B,AD8,J:J,$W$3) -> 3
A9: Ítem | B9: Responsable | C9: Colaborador | D9: CC | E9: C | F9: Proyecto | G9: Trabajos Receso 2026 | H9: Inicio | I9: Termino | J9: Prioridad | K9: Ppto 2022 | L9: Ppto 2023 | M9: Ppto 2024 | N9: Ppto 2025 | O9: Ppto 2026 | P9: Ppto doc. 2026 | Q9: Saldo | R9: Ajuste | S9: % | T9: Superficie | U9: Comentario | AD9: C. Huenchual | AE9: =COUNTIFS(B:B,AD9,J:J,$W$3) -> 0
B10: C.Correa | E10: CSF | F10: PABELLON DE DOCENCIA + HABILITACIÓN | J10: 2 | O10: =25000000+5000000 -> 30000000 | U10: Esquineros | AD10: F.Anselme | AE10: =COUNTIFS(B:B,AD10,J:J,$W$3) -> 5
B11: J.Solis de Ovando | C11: I. Riquelme | D11: 409-5243 INSTITUTO TECNOLOGICO | E11: CRC | F11: EDIFICIO INGENIERÍA (EX TEC) + HABILITACIÓN | G11: Si | I11: 46054 | J11: 1 | O11: =1568182758+73000000 -> 1641182758 | P11: =SUMIFS('Base datos 2026'!J:J,'Base datos 2026'!A:A,D11,'Base datos 2026'!B:B,F11)+'Ingeniería'!N23+'Ingeniería'!N24+'Ingeniería'!N25 -> 1577697306 | Q11: =O11-P11 -> 63485452 | S11: =P11/O11 -> 0.96131726 | U11: Obras , adicional ingeniaria + Grupo electrógeno | AD11: I. Cisternas | AE11: =COUNTIFS(B:B,AD11,J:J,$W$3) -> 1
B12: D.Silva | E12: CJP | F12: TÚNEL, SALIDA Y CALLE PROLONGACIÓN CJPII | J12: 3 | AD12: A. Meza | AE12: =COUNTIFS(B:B,AD12,J:J,$W$3) -> 0
B13: J.Solis de Ovando | C13: I. Riquelme | D13: 409-5506 - CASINO VRAE | E13: CRC | F13: PERMISO + CONSTRUCCION CASINO CRC11 (VRAE) | G13: Si | H13: 46023 | I13: 46266 | J13: 1 | O13: =855200912+40000000 -> 895200912 | P13: =SUMIFS('Base datos 2026'!J:J,'Base datos 2026'!A:A,D13,'Base datos 2026'!B:B,F13) -> 859639867 | Q13: =O13-P13 -> 35561045 | S13: =P13/O13 -> 0.96027591 | T13: 470 | U13: Permiso + Obras + estacionamientos lado contenedores | W13: =(855200912)/T13/X13 -> 45.778789 | X13: 39747.15 | Y13: UF | AD13: I. Riquelme | AE13: =COUNTIFS(B:B,AD13,J:J,$W$3) -> 1
B14: J.Solis de Ovando | D14: 409-5506 - CASINO VRAE | E14: CRC | F14: CASINO CRC11 (VRAE) HABILITACIÓN | H14: 46235 | I14: 46296 | J14: 1 | O14: 100000000 | P14: =SUMIFS('Base datos 2026'!J:J,'Base datos 2026'!A:A,D14,'Base datos 2026'!B:B,F14) -> 98069090 | Q14: =O14-P14 -> 1930910 | S14: =P14/O14 -> 0.9806909 | U14: Habilitación | AD14: A. Meza | AE14: =COUNTIFS(B:B,AD14,J:J,$W$3) -> 0
B15: C.Correa | E15: CHS | F15: HOSPITAL DE SIMULACION CLINICA + HABILITACIÓN | J15: 2 | O15: =20000000+40000000 -> 60000000 | S15: =P15/O15 -> 0 | U15: Habilitar laboratorio clínico +Torniquete de acceso
B16: D.Silva | E16: CCC | F16: CONSTRUCCIÓN SALON DE CONVENCIONES Y EVENTOS, CURACAUTÍN (ETAPA 2) | J16: 2 | O16: 270000000 | S16: =P16/O16 -> 0 | U16: Cubierta, revestimientos, aislación y terminaciones. instalaciones eléctricas y sanitarias. habilitación básica (calefacción, cocina, mobiliario básico)
O20: =SUM(_Obras_2026[Ppto 2026]) -> 831500000
A21: Ítem | B21: Responsable | C21: Colaborador | D21: CC | E21: C | F21: Proyecto | G21: Trabajos Receso 2026 | H21: Inicio | I21: Termino | J21: Prioridad | K21: Ppto 2022 | L21: Ppto 2023 | M21: Ppto 2024 | N21: Ppto 2025 | O21: Ppto 2026 | P21: Ppto doc. 2026 | Q21: Saldo | R21: Ajuste | S21: % | T21: Superficie | U21: Comentario
B22: D.Silva | C22: D.Silva | D22: 409-6293 - CENTRO RECREACIONAL SAN NICOLAS | E22: CCC | F22: OBRAS DE SEGURIDAD, PAISAJISMO CURACAUTIN | G22: Si | H22: 46023 | I22: 46143 | J22: 1 | O22: 40000000 | P22: =SUMIFS('Base datos 2026'!J:J,'Base datos 2026'!A:A,D22,'Base datos 2026'!B:B,F22) -> 2196742 | Q22: =O22-P22 -> 37803258 | S22: =P22/O22 -> 0.05491855 | U22: Barandas de seguridad, cierre perimetral piscina, portones, senderos, paisajismo
B23: J.Solis de Ovando | E23: CRC | F23: ETAPA 2 GRECA CRC (EXTERIOR CASINO + PAISAJISMO) | J23: 2 | O23: 120000000 | T23: 450 | U23: La etapa 2 del proyecto GRECA CRC incluye trabajos en el exterior del nuevo casino. Esto implica la ejecución de obras al aire libre que complementan la infraestructura del edificio, como el condicionamiento de áreas exteriores, acceso, y la implementación de diseño paisajístico para mejorar la estética y funcionalidad de los espacios exteriores del casino y edificio de ingeniería. La intervención busca integrar el entorno construido con áreas verdes y elementos de paisaje.
B24: C.Correa | D24: 409-1722 REMODELACIONES-OBRAS | E24: CRC | F24: PAISAJISMO ESPACIO TRAS CRC18 (ÁREA VERDE) | H24: 46023 | I24: 46174 | J24: 1 | O24: =5000000+10000000 -> 15000000 | P24: =SUMIFS('Base datos 2026'!J:J,'Base datos 2026'!A:A,D24,'Base datos 2026'!B:B,F24) -> 14669999 | Q24: =O24-P24 -> 330001 | S24: =P24/O24 -> 0.97799993 | U24: Trazado zonificaciones, urbanizacion, agua y electricidad
B25: F.Anselme | D25: 409-6293 - CENTRO RECREACIONAL SAN NICOLAS | E25: CRC | F25: MEJORAMIENTO DE ALMACENAMIENTO Y SUMINISTRO DE AGUA POTABLE CRC | H25: 46023 | I25: 46143 | J25: 1 | O25: 25000000 | P25: =SUMIFS('Base datos 2026'!J:J,'Base datos 2026'!A:A,D25,'Base datos 2026'!B:B,F25) -> 0 | Q25: =O25-P25 -> 25000000 | S25: =P25/O25 -> 0 | U25: Sistema autónomo desde la red externa considerando sala de bombas y estanque soterrado
B26: J.Solis de Ovando | E26: CSF | F26: INSTALACIÓN ASCENSOR CSF03 (ACCESIBILIDAD UNIVERSAL) | J26: 2 | O26: 250000000 | S26: =P26/O26 -> 0 | U26: proyecto que aumenta en 1.200 m2 de superficie con acceso universal, dejando al campus con mas del 90% de sus recintos accesibles
B27: C.Correa | E27: CSF | F27: MANTENCIÓN PISO 5 CSF12 (CLIMATIZACIÓN, ELECTRICIDAD Y CUBIERTA) | J27: 2 | O27: =(850*290000)+30000000 -> 276500000 | S27: =P27/O27 -> 0
B28: F.Anselme | E28: CJP | F28: URBANIZACIÓN CAMINO LATERAL CANCHAS | J28: 2 | O28: 45000000 | S28: =P28/O28 -> 0 | U28: Mejorar estacionamientos y veredas para acceso a edificaciones
B29: L. Rios | E29: CSF | F29: OFICINAS MODULARES CSF + URBANIZACION | J29: 2 | O29: 30000000 | S29: =P29/O29 -> 0 | T29: =40*2 -> 80 | U29: Contrucción de modulos de oficinas en CSF, posterior CSF14 - CSF16
E30: CSF | F30: ANTEPROYECTO TEC CSF | J30: 2 | O30: 30000000 | S30: =P30/O30 -> 0
O34: =SUM(Remodelaciones_2026[Ppto 2026]) -> 3181365377
A35: Ítem | B35: Responsable | C35: Colaborador | D35: CC | E35: C | F35: Proyecto | G35: Trabajos Receso 2026 | H35: Inicio | I35: Termino | J35: Prioridad | K35: Ppto 2022 | L35: Ppto 2023 | M35: Ppto 2024 | N35: Ppto 2025 | O35: Ppto 2026 | P35: Ppto doc. 2026 | Q35: Saldo | R35: Ajuste | S35: % | T35: Superficie | U35: Comentario
B36: L. Rios | E36: CBQ | F36: REMODELACIÓN LABORATORIO CLÍNICO UCT (OFICINAS) CBQ03 | J36: 2 | O36: =T36*40000*10 -> 64000000 | S36: =P36/O36 -> 0 | T36: 160 | U36: Remodelación asociada al traslado de TEC al edificio, requiee ampliación habilitación de multiples oficinas
B37: M.Zurita | E37: CDS | F37: NORMALIZACIÓN Y AUMENTO DE POTENCIA ELÉCTRICA 18 DE SEPTIEMBRE | J37: 2 | O37: 25000000 | S37: =P37/O37 -> 0
B38: J.Solis de Ovando | E38: CJP | F38: CAMBIO DE VENTANAS TERMOPANEL Y ENVOLVENTE TERMICA CJP08 ETAPA 2 | J38: 2 | O38: 250000000 | S38: =P38/O38 -> 0 | T38: 919 | U38: El trabajo de "Cambio de Ventanas Termopanel y Envolvente Térmica CJP08 Etapa 2" consiste en mejorar la eficiencia térmica del edificio CJP08 , continuando con los trabnajos del año 2025 , mediante la instalación de ventanas tipo termopanel, que permiten reducir la transferencia de calor entre el interior y exterior, mejorando el confort térmico y disminuyendo la demanda energética. Además, se realiza el mejoramiento de la envolvente térmica, es decir, la capa que aísla térmicamente el edificio.
B39: D.Silva | D39: 409-1722 REMODELACIONES-OBRAS | E39: CJP | F39: ESTUDIO REPARACIÓN ESTRUCTURA DE CUBIERTA EDIFICIO CJP08 | H39: 46082 | I39: 46174 | J39: 1 | O39: 12000000 | P39: =SUMIFS('Base datos 2026'!J:J,'Base datos 2026'!A:A,D39,'Base datos 2026'!B:B,F39) -> 0 | Q39: =O39-P39 -> 12000000 | S39: =P39/O39 -> 0
B40: J.Solis de Ovando | E40: CJP | F40: CAMBIO DE VENTANAS TERMOPANEL Y ENVOLVENTE TERMICA CJP10 | J40: 2 | O40: 150000000 | S40: =P40/O40 -> 0 | T40: 600 | U40: instalación de ventanas tipo termopanel, que permiten reducir la transferencia de calor entre el interior y exterior, mejorando el confort térmico y disminuyendo la demanda energética. Además, se realiza el mejoramiento de la envolvente térmica, es decir, la capa que aísla térmicamente el edificio.
B41: C.Correa | D41: 409-1722 REMODELACIONES-OBRAS | E41: CJP | F41: REGULARIZACION CJP07, CJP10, CJP104 ESPECIALIDADES Y PAGOS | H41: 46023 | I41: 46327 | J41: 1 | O41: 20000000 | P41: =SUMIFS('Base datos 2026'!J:J,'Base datos 2026'!A:A,D41,'Base datos 2026'!B:B,F41) -> 0 | Q41: =O41-P41 -> 20000000 | S41: =P41/O41 -> 0
B42: C.Correa | D42: 409-1722 REMODELACIONES-OBRAS | E42: CJP | F42: REGULARIZACION CJP07, CJP10, CJP104 OBRAS | H42: 46023 | I42: 46327 | J42: 1 | O42: 35000000 | P42: =SUMIFS('Base datos 2026'!J:J,'Base datos 2026'!A:A,D42,'Base datos 2026'!B:B,F42) -> 0 | Q42: =O42-P42 -> 35000000 | S42: =P42/O42 -> 0 | U42: intervenciones en: Tabiques, baños, puertas, franjas podotactil, señaleticas, muebles, otros.
B43: J.Solis de Ovando | E43: CJP | F43: CAMBIO BUTACAS AUDITORIO CJP08 | J43: 2 | O43: 75000000 | S43: =P43/O43 -> 0 | T43: 144 butacas | U43: Cambio de la totalidad de la butacas del auditorio CJP08_260
B44: F.Anselme | D44: 409-1722 REMODELACIONES-OBRAS | E44: CJP | F44: CALEFACCIÓN SALA NUEVA OFICIOS CREATIVOS | H44: 46023 | I44: 46054 | J44: 1 | O44: 22000000 | P44: =SUMIFS('Base datos 2026'!J:J,'Base datos 2026'!A:A,D44,'Base datos 2026'!B:B,F44) -> 0 | Q44: =O44-P44 -> 22000000 | S44: =P44/O44 -> 0
B45: F.Anselme | D45: 409-1722 REMODELACIONES-OBRAS | E45: CJP | F45: RECAMBIO DE CÁMARA DE FRIO PARA CASINO CJP | H45: 46023 | I45: 46082 | J45: 1 | O45: 9000000 | P45: =SUMIFS('Base datos 2026'!J:J,'Base datos 2026'!A:A,D45,'Base datos 2026'!B:B,F45) -> 0 | Q45: =O45-P45 -> 9000000 | S45: =P45/O45 -> 0
B46: F.Anselme | E46: CJP | F46: CAMBIO VENTANAS DVH EN MAL ESTADO CJP05 ETAPA 1 | J46: 2 | O46: =T46*190000 -> 58140000 | S46: =P46/O46 -> 0 | T46: =100+206 -> 306 | U46: Cambio de vidrios en mal estado
...

Sheet Base datos 2026
T1: =SUM(T4:T496) -> 1905200 | U1: =SUM(U4:U496) -> 5595975 | V1: =SUM(V4:V496) -> 43411350 | W1: =SUM(W4:W496) -> 39197456 | X1: =SUM(X4:X496) -> 2200000 | Y1: =SUM(Y4:Y496) -> 0 | Z1: =SUM(Z4:Z496) -> 0 | AA1: =SUM(AA4:AA496) -> 4349400 | ... BU1: =SUM(BU4:BU496) -> 0
T2: Semana 1-Ene | U2: Semana 2-Enero | V2: Semana 3-Ene | W2: Semana 4-Ene | X2: Semana 1-Feb | Y2: Semana 2-Feb | Z2: Semana 3-Febr | AA2: Semana 4-Feb | AB2: Semana 1-Mar | AC2: Semana 2-Marz | AD2: Semana 3-Marzo | AE2: Semana 4-Mar | AF2: Semana 1-Abri | AG2: Semana 2-Abri | AH2: Semana 3-Abril | AI2: Semana 4-Abril | AJ2: Semana 5-Abri | AK2: Semana 1-May | AL2: Semana 2-Mayo | AM2: Semana 3-Mayo | AN2: Semana 4-Mayo | AO2: Semana 1-Jun | AP2: Semana 2-Jun | AQ2: Semana 3-Junio | AR2: Semana 4-Junio | AS2: Semana 1-Juli | AT2: Semana 2-Jul | AU2: Semana 3-Julio | AV2: Semana 4-Julio | AW2: Semana 5-Juli | AX2: Semana 1-Ago | AY2: Semana 2-Agos | AZ2: Semana 3-Agos | BA2: Semana 4-Agos | BB2: Semana 1-Sept | BC2: Semana 2-Septi | BD2: Semana 3-Septi | BE2: Semana 4-Septi | BF2: Semana 5-Septi | BG2: Semana 1-Octu | BH2: Semana 2-Oct | BI2: Semana 3-Octu | BJ2: Semana 4-Octu | BK2: Semana 5-Octu | BL2: Semana 1-Nov | BM2: Semana 2-Novi | BN2: Semana 3-Novi | BO2: Semana 4-Novi | BP2: Semana 1-Dic | BQ2: Semana 2-Dic | BR2: Semana 3-Dici | BS2: Semana 4-Dici | BT2: Semana 5-Dici | BU2: Semana 1-Ene
A3: CC | B3: Proyecto | C3: OP | D3: OC | E3: Tipo Obra | F3: Campus | G3: Edificio | H3: Uso | I3: Descripción | J3: Monto | K3: Pagado | L3: Saldo | M3: % | N3: Contratista | O3: Responsable | P3: RC | Q3: Fecha RC | R3: Column 74 | S3: Δ | T3: 05 al 11 | U3: 12 al 18 | V3: 19 al 25 | W3: 26 al 01 | X3: 02 al 08 | Y3: 09 al 15 | Z3: 16 al 22 | AA3: 23 al 01 | AB3: 02 al 08 | AC3: 09 al 15 | AD3: 16 al 22 | AE3: 23 al 29 | AF3: 30 al 05 | AG3: 06 al 12 | AH3: 13 al 19 | AI3: 20 al 26 | AJ3: 27 al 03 | AK3: 04 al 10 | AL3: 11 al 17 | AM3: 18 al 24 | AN3: 25 al 31 | AO3: 01 al 07 | AP3: 08 al 14 | AQ3: 15 al 21 | AR3: 22 al 28 | AS3: 29 al 05 | AT3: 06 al 12 | AU3: 13 al 19 | AV3: 20 al 26 | AW3: 27 al 02 | AX3: 03 al 09 | AY3: 10 al 16 | AZ3: 17 al 23 | BA3: 24 al 30 | BB3: 31al 06 | BC3: 07 al 13 | BD3: 14 al 20 | BE3: 21 al 27 | BF3: 28 al 04 | BG3: 05 al 11 | BH3: 12 al 18 | BI3: 19 al 25 | BJ3: 26 al 01 | BK3: 02 al 08 | BL3: 09 al 15 | BM3: 16 al 22 | BN3: 23 al 29 | BO3: 24 al 30 | BP3: 30 al 06 | BQ3: 07 al 13 | BR3: 14 al 20 | BS3: 21 al 27 | BT3: 28 al 03 | BU3: 05 al 11
A4: 409-5243 INSTITUTO TECNOLOGICO | B4: EDIFICIO INGENIERÍA (EX TEC) + HABILITACIÓN | C4: 799 | D4: 864 | I4: SOPORTES PARA INSTALACION DE TELEVISORES SALAS DE REUNIONES, SALAS DE CLASES Y LABORARIOS NUEVO EDIFICIO INGENIERIA (ARTURO MEZA) | J4: 5537070 | L4: =J4-K4 -> 5537070 | N4: GYG SERVICIOS | O4: A. Meza | P4: RC-070_26 | Q4: 46121 | R4: 0.73361111 | S4: =J4-K4-(SUM(T4:BU4)) -> 0 | AH4: 5537070
A5: 409-1722 REMODELACIONES-OBRAS | B5: IMPREVISTOS | C5: 793 | D5: 860 | E5: INSTALACIONES | F5: CRC Campus Doctor Luis Rivas Del Canto (vrae) | G5: CRC16 | H5: DOCENCIA | I5: REMODELACION LABORATORIO COMPUTACION CRC16_210 (ARTURO MEZA) | J5: 10154673 | L5: =J5-K5 -> 10154673 | N5: INGERTEMUCO INGENIERIA SPA | O5: A. Meza | P5: RC-008_26 | Q5: 46091 | R5: 0.61634259 | S5: =J5-K5-(SUM(T5:BU5)) -> 0 | AF5: 10154673
A6: 409-5243 INSTITUTO TECNOLOGICO | B6: EDIFICIO INGENIERÍA (EX TEC) + HABILITACIÓN | C6: 1473 | D6: 1578 | E6: INSTALACIONES | F6: CRC Campus Doctor Luis Rivas Del Canto (vrae) | G6: CRC10 | I6: RACK PARA DATA CENTER NUEVO EDIFICIO FACULTAD DE INGENIERIA (ARTURO MEZA)PROVEEDOR ADJUDICADO CUMPLE CON TODAS LAS ESPECIFICACIONES TECNICAS. | J6: 3704470 | L6: =J6-K6 -> 3704470 | N6: GYG SERVICIOS | O6: A. Meza | P6: RC-036_26 | Q6: 46101 | R6: 0.45989583 | S6: =J6-K6-(SUM(T6:BU6)) -> 0 | AE6: 3704470
A7: 409-5243 INSTITUTO TECNOLOGICO | B7: EDIFICIO INGENIERÍA (EX TEC) + HABILITACIÓN | C7: 1770 | D7: 1786 | E7: ALHAJAMIENTO | F7: CRC Campus Doctor Luis Rivas Del Canto (vrae) | G7: CRC10 | I7: TELEVISORES PARA SALAS DE CLASES, REUNIONES Y LABORATORIOS NUEVO EDIFICIO INGENIERIA (ARTURO MEZA) | J7: 17043200 | L7: =J7-K7 -> 17043200 | N7: GYG SERVICIOS | O7: A. Meza | P7: RC-048_26 | Q7: 46107 | R7: 0.58019676 | S7: =J7-K7-(SUM(T7:BU7)) -> 0 | AF7: 17043200
A8: 409-5243 INSTITUTO TECNOLOGICO | B8: EDIFICIO INGENIERÍA (EX TEC) + HABILITACIÓN | C8: 2497 | D8: 2421 | E8: INSTALACIONES | F8: CRC Campus Doctor Luis Rivas Del Canto (vrae) | G8: CRC10 | I8: MODIFICACION DE ENCHUFES Y HDMI PARA INSTALACION DE TV EN SALAS DE CLASES EDIFICIO FAC. DE INGENIERIA (ARTURO MEZA) | J8: 799442 | L8: =J8-K8 -> 799442 | N8: GYG SERVICIOS | O8: A. Meza | P8: RC-199_26 | Q8: 46162 | R8: 0.57662037 | S8: =J8-K8-(SUM(T8:BU8)) -> 0 | AI8: 799442
A9: 409-5243 INSTITUTO TECNOLOGICO | B9: EDIFICIO INGENIERÍA (EX TEC) + HABILITACIÓN | C9: 2714 | D9: 2483 | E9: INSTALACIONES | F9: CRC Campus Doctor Luis Rivas Del Canto (vrae) | G9: CRC10 | I9: GRUPO ELECTROGENO EDIFICIO CRC10 FACULTAD DE INGENIERIA (ARTURO MEZA) | J9: 15170428 | L9: =J9-K9 -> 15170428 | N9: ELECTROPOWER | O9: A. Meza | P9: RC-189_26 | Q9: 46160 | R9: 0.61135417 | S9: =J9-K9-(SUM(T9:BU9)) -> 0 | AL9: 15170428
A10: 409-1722 REMODELACIONES-OBRAS | B10: IMPREVISTOS | C10: 276 | D10: 331 | E10: AUMENTO DE OBRA | F10: CLE Nuestra Señora de Lourdes | G10: CHS01 | H10: DOCENCIA | I10: AUMENTO DE OBRA OC 8157 ADICIONALES OBRAS POST CONTRUCCION SEGUN DETALLE (CRISTOBAL CORREA) | J10: 9440482 | L10: =J10-K10 -> 9440482 | N10: ROMO Y CADI LIMITADA | O10: C.Correa | Q10: #N/A | S10: =J10-K10-(SUM(T10:BU10)) -> 0 | AK10: 9440482
A11: 409-1722 REMODELACIONES-OBRAS | B11: IMPREVISTOS | C11: 277 | D11: 361 | E11: AUMENTO DE OBRA | F11: CLE Nuestra Señora de Lourdes | G11: CHS01 | H11: DOCENCIA | I11: AUMENTO DE OBRA OC.13558 ADICIONAL MUEBLES HOSPITAL DE SIMULACION CLINICA (CRISTOBAL CORREA) | J11: 5595975 | L11: =J11-K11 -> 5595975 | N11: ESPACIO MUEBLES LIMITADA | O11: C.Correa | Q11: #N/A | S11: =J11-K11-(SUM(T11:BU11)) -> 0 | U11: 5595975
A12: 409-1722 REMODELACIONES-OBRAS | B12: IMPREVISTOS | C12: 678 | D12: 738 | E12: COMPRA ELEMENTOS | F12: CRC Campus Doctor Luis Rivas Del Canto (vrae) | G12: CRC16 | H12: DOCENCIA | I12: MOBILIARIO HABILITACION LABORATORIO COMPUTACIÓN CRC16_210 (CRISTOBAL CORREA) | J12: 4405800 | L12: =J12-K12 -> 4405800 | N12: MULTIMUEBLES | O12: C.Correa | Q12: #N/A | S12: =J12-K12-(SUM(T12:BU12)) -> 0 | AB12: 4405800
A13: 409-1722 REMODELACIONES-OBRAS | B13: IMPREVISTOS | C13: 1475 | D13: 1475 | E13: REGULARIZACION | I13: ASESORIAS CES, CERTIFICACION EDIFICIOS SUSTENTABLES PABELLON DOCENTE Y HOSPITAL DE SIMULACION (CRISTOBAL CORREA) | J13: 15015909 | L13: =J13-K13 -> 15015909 | N13: 88 ARQUITECTOS LIMITADA | O13: C.Correa | P13: RC-031_26; RC-033_26 | Q13: #N/A | S13: =J13-K13-(SUM(T13:BU13)) -> 0 | AD13: 15015909
A14: 409-1722 REMODELACIONES-OBRAS | B14: IMPREVISTOS | C14: 2863 | D14: 2771 | E14: OTROS | F14: CSF Campus San Francisco | G14: CSF21 | I14: INSTALACION GOMAS REFLECTANTES EN PILARES ESTACIONAMIENTO CSF21 (CRISTOBAL CORREA) | J14: 1427829 | L14: =J14-K14 -> 1427829 | N14: CONSTRUCTORA IGECE LIMITADA | O14: C.Correa | P14: RC-167_26 | Q14: 46155 | R14: 0.50836806 | S14: =J14-K14-(SUM(T14:BU14)) -> 0 | AJ14: 1427829
A15: 409-1722 REMODELACIONES-OBRAS | B15: IMPREVISTOS | C15: 278 | D15: 233 | E15: AUMENTO DE OBRA | F15: CCC Campus Curacautin | H15: OTROS | I15: AUMENTO DE OBRA OC.3946-2025 CONSTRUCCIÓN CABAÑAS CENTRO RECREACIONAL CURACAUTIN. RESPONSABLE: DAVID SILVA. SEGUN COTIZACION N 522 | J15: 43411350 | L15: =J15-K15 -> 43411350 | N15: CONSTRUCTORA RUKATAMI | O15: D.Silva | Q15: #N/A | S15: =J15-K15-(SUM(T15:BU15)) -> 0 | V15: 43411350
A16: 409-1722 REMODELACIONES-OBRAS | B16: OBRAS DE SEGURIDAD, PAISAJISMO CURACAUTIN | C16: 674 | D16: 705 | E16: COMPRA ELEMENTOS | F16: CCC Campus Curacautin | G16: CCC | H16: ESPACIOS COMUNES | I16: SEÑALETICA CENTRO RECREACIONAL CURACAUTIN (DAVID SILVA) | J16: 4921911 | L16: =J16-K16 -> 4921911 | N16: DSIETE SPA | O16: D.Silva | P16: RC-282 | Q16: 46083 | R16: 0.71075231 | S16: =J16-K16-(SUM(T16:BU16)) -> 0 | AB16: 4921911
A17: 409-1722 REMODELACIONES-OBRAS | B17: MANTENCIÓN ESTRUCTURA MADERA LAMINADA PILARES Y VIGAS CSF14 - CSF16 | C17: 791 | D17: 858 | E17: OTROS | F17: CSF Campus San Francisco | H17: ESPACIOS COMUNES | I17: REPARACION Y MANTENCION DE ESTRUCTURAS DE MADELA LAMINADA EDIFICO CSF14, CSF15 Y CSF16 (DAVID SILVA) | J17: 94737758 | L17: =J17-K17 -> 94737758 | N17: AVANTI LTDA | O17: D.Silva | P17: RC-002_26; RC-118_26 | Q17: #N/A | S17: =J17-K17-(SUM(T17:BU17)) -> 0 | AC17: 68426229 | AJ17: 26311529
A18: 409-1722 REMODELACIONES-OBRAS | B18: CRC05 MEJORAS HABITABILIDAD INTERIOR | C18: 792 | D18: 859 | E18: REMODELACION | F18: CRC Campus Doctor Luis Rivas Del Canto (vet) | G18: CRC05 | H18: DOCENCIA | I18: MEJORAMIENTO TERMICO DE CUBIERTA SEGUNDO NIVEL EDIFICIO CRC05 (DAVID SILVA) | J18: 44864047 | L18: =J18-K18 -> 44864047 | N18: CONSTRUCTORA IGECE LIMITADA | O18: D.Silva | P18: RC-010_26; RC-119_26 | Q18: #N/A | S18: =J18-K18-(SUM(T18:BU18)) -> 0 | AC18: 40377642 | AJ18: 4486405
A19: 409-1722 REMODELACIONES-OBRAS | B19: IMPREVISTOS | C19: 1138 | D19: 1819 | E19: OTROS | F19: CSF Campus San Francisco | G19: CJP15 | H19: ESPACIOS COMUNES | I19: MEJORAMIENTO CAMARINES, DUCHAS GIMNASIO CAMPUS SAN FRANCISCO EDIFICIO 15 (DAVID SILVA) | J19: 19801637 | L19: =J19-K19 -> 19801637 | N19: ROMO Y CADI LIMITADA | O19: D.Silva | P19: RC-066_26 | Q19: 46118 | R19: 0.64304398 | S19: =J19-K19-(SUM(T19:BU19)) -> 0 | AF19: 19801637
A20: 409-1722 REMODELACIONES-OBRAS | B20: IMPREVISTOS | C20: 2637 | D20: 2500 | E20: ALHAJAMIENTO | F20: CRC Campus Doctor Luis Rivas Del Canto (vrae) | G20: CRC18 | I20: REPISAS PARA PAÑOL CARRERA INGENIERÍA ELÉCTRICA CRC18_180 FELIPE ANSELME) | J20: 1328150 | L20: =J20-K20 -> 1328150 | N20: MULTIMUEBLES | O20: F.Anselme | P20: RC-131_26 | Q20: 46140 | R20: 0.61581019 | S20: =J20-K20-(SUM(T20:BU20)) -> 0 | AI20: 1328150
A21: 409-1722 REMODELACIONES-OBRAS | B21: BIBICLETERO CRC (VRAE) | C21: 794 | D21: 861 | I21: CONSTRUCCION BICICLETERO CAMPUS LUIS RIVAS DEL CANTO , COSTADO CASETA GUARDIA (ISABEL RIQUELME) | J21: 16082457 | L21: =J21-K21 -> 16082457 | N21: GATICAR SPA | O21: I. Riquelme | P21: RC-283 | Q21: 46084 | R21: 0.4259838 | S21: =J21-K21-(SUM(T21:BU21)) -> 0 | AB21: 16082457
A22: 409-1722 REMODELACIONES-OBRAS | B22: BIBICLETERO CRC (VRAE) | C22: 1223 | D22: 1230 | E22: AUMENTO DE OBRA | F22: CRC Campus Doctor Luis Rivas Del Canto (vrae) | H22: ESPACIOS COMUNES | I22: INSTALACIÓN DE CANAL DE AGUAS LLUVIAS Y POLICARBONATO EN PARED TRAS ENCHUFES BICICLETERO CAMPUS LUIS RIVAS DEL CANTO (FELIPE ANSELME) | J22: 511700 | L22: =J22-K22 -> 511700 | N22: GATICAR SPA | O22: I. Riquelme | P22: RC-021_26 | Q22: 46092 | R22: 0.82554398 | S22: =J22-K22-(SUM(T22:BU22)) -> 0 | AC22: 511700
A23: 409-5243 INSTITUTO TECNOLOGICO | B23: EDIFICIO INGENIERÍA (EX TEC) + HABILITACIÓN | C23: 91 | D23: 66 | E23: AUMENTO DE OBRA | F23: CRC Campus Doctor Luis Rivas Del Canto (vet) | G23: CRC10 | H23: DOCENCIA | I23: AUMENTO DE OBRA OC. 9031 CONSTRUCCION EDIFICIO INGENIERIA CRC (EX TEC) JUAN IGNACIO SOLIS DE OVANDO | J23: 664691208 | K23: =186646382+118263881+132505939 -> 437416202 | L23: =J23-K23 -> 227275006 | N23: LSA INGENIERIA Y CONSTRUCCIÓN E.I.R.L. | O23: J.Solis de Ovando | P23: RC-286 | Q23: 46085 | R23: 0.61953704 | S23: =J23-K23-(SUM(T23:BU23)) -> 18000001 | AB23: 209275005
A24: 409-5506 - CASINO VRAE | B24: PERMISO + CONSTRUCCION CASINO CRC11 (VRAE) | C24: 1434 | D24: 1426 | E24: OBRA NUEVA | F24: CRC Campus Doctor Luis Rivas Del Canto (vrae) | G24: CRC11 | H24: OTROS | I24: Nuevo Edificio Casino CRC | J24: 855200912 | L24: =J24-K24 -> 855200912 | N24: LSA INGENIERIA Y CONSTRUCCIÓN E.I.R.L. | O24: J.Solis de Ovando | P24: RC-053_26; RC-054_26; RC-140_26; RC-209_26; RC-275_26 | Q24: #N/A | S24: =J24-K24-(SUM(T24:BU24)) -> -1 | AF24: 144479558 | AJ24: 69931126 | AO24: 167082324 | AS24: 155127189 | AW24: 178457507 | BB24: 97363163 | BF24: 42760046
A25: 409-1722 REMODELACIONES-OBRAS | B25: IMPREVISTOS | C25: 503 | D25: 449 | E25: AUMENTO DE OBRA | F25: CSF Campus San Francisco | G25: CSF01 | H25: ADMINISTRACION | I25: AUMENTO DE OBRA OC.11875 REMODELACION OFICINAS Y ATENCION A PUBLICO CSF01 ED. CAEP (JUAN IGNACIO SOLIS) | J25: 1522909 | L25: =J25-K25 -> 1522909 | N25: CONSTRUCTORA INGETRAPP | O25: J.Solis de Ovando | P25: RC-281 | Q25: 46083 | R25: 0.56324074 | S25: =J25-K25-(SUM(T25:BU25)) -> 0 | AB25: 1522909
A26: 409-1722 REMODELACIONES-OBRAS | B26: IMPREVISTOS | C26: 800 | D26: 733 | E26: REMODELACION | F26: CRC Campus Doctor Luis Rivas Del Canto (vrae) | G26: CRC18 | H26: ESPACIOS COMUNES | I26: CONSTRUCCION DE PAÑOL Y REHABILITACION DE FRONTIS CRC18 (JUAN IGNACIO SOLIS) | J26: 23807821 | L26: =J26-K26 -> 23807821 | N26: CONSTRUCTORA ALPLAS SPA | O26: J.Solis de Ovando | P26: RC-279; RC-086_26 | Q26: #N/A | S26: =J26-K26-(SUM(T26:BU26)) -> -5881058.7 | W26: =$L$15*0.3 -> 13023405 | AB26: 10713519 | AH26: 5951955.7
A27: 409-1722 REMODELACIONES-OBRAS | B27: REMODELACION LAB. SUELOS , CONSTRUCCION DE OFICINAS CPH02 (PHILLIPPI) | C27: 796 | D27: 752 | I27: ADECUACION DE ESPACIOS PARA OFICINAS CPH02 ESPACIOS EX LABORATORIO DE SUELOS (PHILLIPPI B) (JUAN IGNACIO SOLIS) | J27: 53297921 | L27: =J27-K27 -> 53297921 | N27: CONSTRUCTORA INGETRAPP | O27: J.Solis de Ovando | P27: RC-249_26; RC-250_26 | Q27: #N/A | S27: =J27-K27-(SUM(T27:BU27)) -> 0 | W27: 15989376 | AB27: 21319172 | AI27: 15989373
A28: 409-5243 INSTITUTO TECNOLOGICO | B28: EDIFICIO INGENIERÍA (EX TEC) + HABILITACIÓN | C28: 788 | D28: 731 | E28: ALHAJAMIENTO | F28: CRC Campus Doctor Luis Rivas Del Canto (vrae) | G28: CRC10 | H28: ADMINISTRACION | I28: HABILITACION MOBILIARIO OFICINAS 3ER NIVEL EDIFICIO INGENIERIA CRC10 (JUAN IGNACIO SOLIS) | J28: 25523715 | L28: =J28-K28 -> 25523715 | N28: ESPACIO MUEBLES LIMITADA | O28: J.Solis de Ovando | P28: RC-004_26; RC-006_26 | Q28: #N/A | S28: =J28-K28-(SUM(T28:BU28)) -> 1.5 | W28: =J28*0.3 -> 7657114.5 | AB28: 17866599
A29: 409-5243 INSTITUTO TECNOLOGICO | B29: EDIFICIO INGENIERÍA (EX TEC) + HABILITACIÓN | C29: 789 | D29: 732 | E29: ALHAJAMIENTO | F29: CRC Campus Doctor Luis Rivas Del Canto (vrae) | G29: CRC10 | H29: DOCENCIA | I29: MUEBLES HABILITACION LABORATORIO DE COMPUTACION EDIFICIO INGENIERIA CRC10 (JUAN IGNACIO SOLIS) | J29: 8425200 | L29: =J29-K29 -> 8425200 | N29: ESPACIO MUEBLES LIMITADA | O29: J.Solis de Ovando | P29: RC-003_26; RC-005_26 | Q29: #N/A | S29: =J29-K29-(SUM(T29:BU29)) -> 0 | W29: =J29*0.3 -> 2527560 | AC29: 5897640
A30: 409-5243 INSTITUTO TECNOLOGICO | B30: EDIFICIO INGENIERÍA (EX TEC) + HABILITACIÓN | C30: 1803 | D30: 1788 | E30: ALHAJAMIENTO | F30: CRC Campus Doctor Luis Rivas Del Canto (vrae) | G30: CRC10 | I30: MOBILITARIO INTERIOR CLOSET ESCALA CON CERRADURA PISOS 1,2,3 ED. INGENIERIA CRC10 (JUAN IGNACION SOLIS) | J30: 856800 | L30: =J30-K30 -> 856800 | N30: ESPACIO MUEBLES LIMITADA | O30: J.Solis de Ovando | P30: RC-064_26 | Q30: 46115 | R30: 0.9966088 | S30: =J30-K30-(SUM(T30:BU30)) -> 0 | AI30: 856800
A31: 409-1722 REMODELACIONES-OBRAS | B31: IMPREVISTOS | C31: 1806 | D31: 1845 | E31: AUMENTO DE OBRA | F31: CRC Campus Doctor Luis Rivas Del Canto (vrae) | G31: CRC18 | I31: AUMENTO DE OBRA OC.733 REVESTIMIENTO PERIMETRAL CRC18 GALPON 2 GRANDE (JUAN IGNACIO SOLIS) | J31: 1536340 | L31: =J31-K31 -> 1536340 | N31: CONSTRUCTORA ALPLAS SPA | O31: J.Solis de Ovando | P31: RC-068_26 | Q31: 46120 | R31: 0.41576389 | S31: =J31-K31-(SUM(T31:BU31)) -> 0 | AH31: 1536340
A32: 409-5243 INSTITUTO TECNOLOGICO | B32: EDIFICIO INGENIERÍA (EX TEC) + HABILITACIÓN | C32: 2055 | D32: 1991 | E32: ALHAJAMIENTO | F32: CRC Campus Doctor Luis Rivas Del Canto (vrae) | G32: CRC10 | I32: PIZARRAS MOVIL, HABILITACION SALA DE ESTUDIOS EDIFICIO INGENIERIA CRC10 (JUAN IGNACION SOLIS) | J32: 1266755 | L32: =J32-K32 -> 1266755 | N32: MELMAN SPA | O32: J.Solis de Ovando | Q32: #N/A | S32: =J32-K32-(SUM(T32:BU32)) -> 0 | AJ32: 1266755
A33: 409-5243 INSTITUTO TECNOLOGICO | B33: EDIFICIO INGENIERÍA (EX TEC) + HABILITACIÓN | C33: 2071 | D33: 2025 | E33: ALHAJAMIENTO | F33: CRC Campus Doctor Luis Rivas Del Canto (vrae) | G33: CRC10 | I33: EMPAVONADO DE OFICINAS Y CASINO EDIFICIO CRC10 (JUAN IGNACIOS SOLIS) | J33: 3599892 | L33: =J33-K33 -> 3599892 | O33: J.Solis de Ovando | P33: RC-013; RC-014; RC-015; RC-016; RC-019; RC-114_26 | Q33: #N/A | S33: =J33-K33-(SUM(T33:BU33)) -> 0 | AI33: 3599892
A34: 409-5243 INSTITUTO TECNOLOGICO | B34: EDIFICIO INGENIERÍA (EX TEC) + HABILITACIÓN | C34: 2809 | D34: 2692 | E34: ALHAJAMIENTO | F34: CRC Campus Doctor Luis Rivas Del Canto (vrae) | G34: CRC10 | I34: HABILITACION MOBILIARIO LABORATORIO DE PRE Y POST GRADO FACULTAD DE INGENIERIA (JUAN IGNACION SOLIS) | J34: 28468370 | L34: =J34-K34 -> 28468370 | N34: ESPACIO MUEBLES LIMITADA | O34: J.Solis de Ovando | P34: RC-156_26; RC-157_26 | Q34: #N/A | S34: =J34-K34-(SUM(T34:BU34)) -> 0 | AK34: 28468370
A35: 409-1722 REMODELACIONES-OBRAS | B35: MEJORAS ESPACIOS INTERNAS CSF10 (CREDITO) | C35: 651 | D35: 633 | E35: INSTALACIONES | F35: CSF Campus San Francisco | G35: CSF10 | H35: ADMINISTRACION | I35: INSTALACION EQUIPO DE AIRE ACONDICIONADO , MAS TRASLADO DE DOS EQUIPOS, CSF10_200 CREDITO Y RECAUDACION (LEONOR RIOS) | J35: 1997415 | L35: =J35-K35 -> 1997415 | N35: FLAVIA OYARZUN SOTO | O35: L. Rios | Q35: #N/A | S35: =J35-K35-(SUM(T35:BU35)) -> 0 | AB35: 1997415
A36: 409-1722 REMODELACIONES-OBRAS | B36: SEÑALETICA OFICINAS TERMINO EN CJP, CSF Y CRC | C36: 2790 | D36: 2598 | E36: ALHAJAMIENTO | F36: CRC Campus Doctor Luis Rivas Del Canto (vrae) | G36: CRC10 | I36: SEÑALÉTICA NOMBRE CRC10 Y NUMEROS EN CSL01 (LEONOR RIOS) | J36: 1074618 | L36: =J36-K36 -> 1074618 | N36: PUA DISEÑO | O36: L. Rios | P36: RC-115_26 | Q36: 46136 | R36: 0.44501157 | S36: =J36-K36-(SUM(T36:BU36)) -> 0 | AI36: 1074618
A37: 409-1722 REMODELACIONES-OBRAS | B37: BIBLIOTECA CSF02 ETAPA 2 Y 3, ELECTRICO | C37: 3170 | D37: 2873 | E37: REMODELACION | F37: CSF Campus San Francisco | G37: CSF02 | I37: REMODELACION PROYECTO ETAPA 2 Y 3 BIBLIOTECA CAMPUS SAN FRANCISCO (LEONOR RIOS) | J37: 12630236 | L37: =J37-K37 -> 12630236 | N37: CONSTRUCTORA Y SERVICIOS S-TEC SPA | O37: L. Rios | P37: RC-112_26 | Q37: 46135 | R37: 0.56186343 | S37: =J37-K37-(SUM(T37:BU37)) -> 0 | AJ37: 12630236
A38: 409-1722 REMODELACIONES-OBRAS | B38: OBRAS DE SEGURIDAD, PAISAJISMO CURACAUTIN | C38: 666 | D38: 663 | E38: INSTALACIONES | F38: CCC Campus Curacautin | G38: CCC | H38: ESPACIOS COMUNES | I38: INSTALACION SERVICIOS DE INTERNET SATELITAL CENTRO RECREACIONAL CURACAUTIN (ARTURO MEZA) | J38: 4699310 | L38: =J38-K38 -> 4699310 | N38: GYG SERVICIOS | O38: M.Zurita | P38: RC-164_26 | Q38: 46154 | R38: 0.656875 | S38: =J38-K38-(SUM(T38:BU38)) -> 0 | AJ38: 4699310
A39: 409-5243 INSTITUTO TECNOLOGICO | B39: EDIFICIO INGENIERÍA (EX TEC) + HABILITACIÓN | C39: 699 | D39: 703 | E39: INSTALACIONES | F39: CRC Campus Doctor Luis Rivas Del Canto (vrae) | G39: CRC10 | H39: DOCENCIA | I39: INSTALACIÓN DE ACCESS POINT EN EDIFICIO EX TEC (MAURICIO ZURITA) | J39: 2416890 | L39: =J39-K39 -> 2416890 | N39: GYG SERVICIOS | O39: M.Zurita | P39: RC-045_26 | Q39: 46107 | R39: 0.4341088 | S39: =J39-K39-(SUM(T39:BU39)) -> 0 | AF39: 2416890
A40: 409-1722 REMODELACIONES-OBRAS | B40: BIBLIOTECA CSF02 ETAPA 2 Y 3, ELECTRICO | C40: 803 | D40: 869 | E40: INSTALACIONES | F40: CSF Campus San Francisco | G40: CSF02 | H40: DOCENCIA | I40: REMODELACION PROYECTO ELECTRICO ETAPA 2 Y 3 EDIFICIO BIBLIOTECA, LABORATORIO DE COMPUTACION CSF02-311/CSF02_321 (ARTURO MEZA) | J40: 30530278 | L40: =J40-K40 -> 30530278 | N40: ELEKTRICA | O40: M.Zurita | P40: RC-288 | Q40: 46085 | R40: 0.72351852 | S40: =J40-K40-(SUM(T40:BU40)) -> 0 | AB40: 24424223 | AK40: 6106055
...

Sheet Base de datoas ≤ 2025
Q1: =SUM(Q4:Q1002) -> 0 | R1: =SUM(R4:R1002) -> 0 | S1: =SUM(S4:S1002) -> 0 | T1: =SUM(T4:T1002) -> 18533845 | U1: =SUM(U4:U1002) -> 0 | V1: =SUM(V4:V1002) -> 0 | W1: =SUM(W4:W1002) -> 0 | X1: =SUM(X4:X1002) -> 0 | ... BR1: =SUM(BR4:BR1002) -> 0
Q2: Semana 1-Ene | R2: Semana 2-Enero | S2: Semana 3-Ene | T2: Semana 4-Ene | U2: Semana 1-Feb | V2: Semana 2-Feb | W2: Semana 3-Febr | X2: Semana 4-Feb | Y2: Semana 1-Mar | Z2: Semana 2-Marz | AA2: Semana 3-Marzo | AB2: Semana 4-Mar | AC2: Semana 1-Abri | AD2: Semana 2-Abri | AE2: Semana 3-Abril | AF2: Semana 4-Abril | AG2: Semana 5-Abri | AH2: Semana 1-May | AI2: Semana 2-Mayo | AJ2: Semana 3-Mayo | AK2: Semana 4-Mayo | AL2: Semana 1-Jun | AM2: Semana 2-Jun | AN2: Semana 3-Junio | AO2: Semana 4-Junio | AP2: Semana 1-Juli | AQ2: Semana 2-Jul | AR2: Semana 3-Julio | AS2: Semana 4-Julio | AT2: Semana 5-Juli | AU2: Semana 1-Ago | AV2: Semana 2-Agos | AW2: Semana 3-Agos | AX2: Semana 4-Agos | AY2: Semana 1-Sept | AZ2: Semana 2-Septi | BA2: Semana 3-Septi | BB2: Semana 4-Septi | BC2: Semana 5-Septi | BD2: Semana 1-Octu | BE2: Semana 2-Oct | BF2: Semana 3-Octu | BG2: Semana 4-Octu | BH2: Semana 5-Octu | BI2: Semana 1-Nov | BJ2: Semana 2-Novi | BK2: Semana 3-Novi | BL2: Semana 4-Novi | BM2: Semana 1-Dic | BN2: Semana 2-Dic | BO2: Semana 3-Dici | BP2: Semana 4-Dici | BQ2: Semana 5-Dici | BR2: Semana 1-Ene
A3: CC | B3: Proyecto | C3: Año | D3: OC | E3: Tipo Obra | F3: Campus | G3: Edificio | H3: Uso | I3: Descripción | J3: Monto | K3: Pagado | L3: Saldo | M3: % | N3: Contratista | O3: Responsable | P3: Δ | Q3: 05 al 11 | R3: 12 al 18 | S3: 19 al 25 | T3: 26 al 01 | U3: 02 al 08 | V3: 09 al 15 | W3: 16 al 22 | X3: 23 al 01 | Y3: 02 al 08 2 | Z3: 09 al 15 2 | AA3: 16 al 22 2 | AB3: 23 al 29 | AC3: 30 al 05 | AD3: 06 al 12 | AE3: 13 al 19 | AF3: 20 al 26 | AG3: 27 al 03 | AH3: 04 al 10 | AI3: 11 al 17 | AJ3: 18 al 24 | AK3: 25 al 31 | AL3: 01 al 07 | AM3: 08 al 14 | AN3: 15 al 21 | AO3: 22 al 28 | AP3: 29 al 05 | AQ3: 06 al 12 2 | AR3: 13 al 19 2 | AS3: 20 al 26 2 | AT3: 27 al 02 | AU3: 03 al 09 | AV3: 10 al 16 | AW3: 17 al 23 | AX3: 24 al 30 | AY3: 31al 06 | AZ3: 07 al 13 | BA3: 14 al 20 | BB3: 21 al 27 | BC3: 28 al 04 | BD3: 05 al 11 2 | BE3: 12 al 18 2 | BF3: 19 al 25 2 | BG3: 26 al 01 2 | BH3: 02 al 08 3 | BI3: 09 al 15 3 | BJ3: 16 al 22 3 | BK3: 23 al 29 2 | BL3: 24 al 30 2 | BM3: 30 al 06 | BN3: 07 al 13 2 | BO3: 14 al 20 2 | BP3: 21 al 27 2 | BQ3: 28 al 03 | BR3: 05 al 11 3
A4: 409-5243 INSTITUTO TECNOLOGICO | B4: EDIFICIO INGENIERÍA (EX TEC) + HABILITACIÓN | C4: 2024 | D4: 8022 | E4: AUMENTO DE OBRA | F4: CRC Campus Doctor Luis Rivas Del Canto (vrae) | G4: CRC10 | H4: DOCENCIA | I4: Edificio Ingeniería (ex TEC) | J4: 4408299870 | K4: =200000000+214576722+451540786+242312734+224174189+155623352+252294712+201102519+155455601+218152853+324983774+366374243+153086824+152511772+102298014+203742698+184685827+170139342 -> 3973055962 | L4: =J4-K4 -> 435243908 | N4: LSA INGENIERIA Y CONSTRUCCIÓN E.I.R.L. | O4: J.Solis de Ovando | P4: =J4-K4-(SUM(Q4:BR4)) -> 0 | Y4: =185222684 -> 185222684 | AH4: 250021224
A5: 409-5243 INSTITUTO TECNOLOGICO | B5: EDIFICIO INGENIERÍA (EX TEC) + HABILITACIÓN | C5: 2025 | D5: 9031 | E5: AUMENTO DE OBRA | F5: CRC Campus Doctor Luis Rivas Del Canto (vrae) | G5: CRC10 | H5: DOCENCIA | I5: AO N°1 Edificio Ingeniería (ex TEC) | J5: 456637235 | K5: =81204459+170270732+89858090+110752237 -> 452085518 | L5: =J5-K5 -> 4551717 | N5: LSA INGENIERIA Y CONSTRUCCIÓN E.I.R.L. | O5: J.Solis de Ovando | P5: =J5-K5-(SUM(Q5:BR5)) -> 0 | AI5: 4551717
A6: 409-5243 INSTITUTO TECNOLOGICO | B6: EDIFICIO INGENIERÍA (EX TEC) + HABILITACIÓN | C6: 2024 | D6: 4075 | E6: OTROS | F6: CRC Campus Doctor Luis Rivas Del Canto (vrae) | G6: CRC10 | H6: DOCENCIA | I6: Arquitectura Edificio Ingeniería (ex TEC) | J6: 86080359 | K6: =24432144+7173363+12912054+7173363 -> 51690924 | L6: =J6-K6 -> 34389435 | N6: SOCIEDAD DE PROFESIONALES BAIXAS Y DEL RIO ARQUITECTOS LIMITADA | O6: J.Solis de Ovando | P6: =J6-K6-(SUM(Q6:BR6)) -> 14304018 | AF6: 7173363 | AK6: 8608036.1 | AO6: 4304018
C7: 2023 | D7: 12187 | I7: Estudio Túnel | J7: 81691879 | K7: =12253782+12953656+8217395+4686425 -> 38111258 | L7: =J7-K7 -> 43580621 | N7: SUBTERRA INGENIERIA LIMITADA | O7: F.Anselme
C8: 2024 | D8: 8440 | I8: Revisores CES Pabelón y Hospital | J8: 4219946 | K8: 2260686 | L8: =J8-K8 -> 1959260 | N8: 88 ARQUITECTOS LIMITADA | O8: C.Correa
C9: 2023 | D9: 1754 | I9: Asesoria CES Hospital | J9: 17147240 | K9: =5621069+2953620+7426964 -> 16001653 | L9: =J9-K9 -> 1145587 | N9: 88 ARQUITECTOS LIMITADA | O9: C.Correa
C10: 2023 | D10: 1155 | I10: Asesoria CES Pabellon | J10: 9073025 | K10: =2721907+5443815 -> 8165722 | L10: =J10-K10 -> 907303 | N10: 88 ARQUITECTOS LIMITADA | O10: C.Correa
C11: 2025 | D11: 3946 | G11: CCC | I11: Cabañas Curacautín | J11: 316857372 | K11: =95057212+27725020+27725020+75253626+75253626 -> 301014504 | L11: =J11-K11 -> 15842868 | N11: CONSTRUCTORA RUKATAMI | O11: D.Silva | P11: =J11-K11-(SUM(Q11:BR11)) -> -0.6 | AF11: 15842869
C12: 2025 | D12: 7844 | I12: Regularización PE cjp07/cjp10/cjp104 | J12: 10833477 | K12: 2540943 | L12: =J12-K12 -> 8292534 | O12: C.Correa | P12: =J12-K12-(SUM(Q12:BR12)) -> 0 | AK12: 4146267 | AT12: 4146267
C13: 2025 | D13: 10964 | I13: Mobiliario Biblioteca CSF02 etapa 2 y 3 | J13: 67524777 | K13: 20257433 | L13: =J13-K13 -> 47267344 | N13: MELMAN SPA | O13: L. Rios | P13: =J13-K13-(SUM(Q13:BR13)) -> 0.1 | AE13: 47267344
C14: 2025 | D14: 11875 | I14: Remodelación Dirección General Estudiantil CSF | J14: 24367129 | K14: =7310138+7421966 -> 14732104 | L14: =J14-K14 -> 9635025 | N14: CONSTRUCTORA INGETRAPP | O14: J.Solis de Ovando | P14: =J14-K14-(SUM(Q14:BR14)) -> 0 | T14: 9635025
A15: 409-5243 INSTITUTO TECNOLOGICO | C15: 2025 | D15: 13112 | I15: Armado muebles Edificio de Ingenieria UCT (exTEC) | J15: 13917050 | K15: 5566820 | L15: =J15-K15 -> 8350230 | N15: ESPACIO MUEBLES LIMITADA | O15: J.Solis de Ovando | P15: =J15-K15-(SUM(Q15:BR15)) -> 0 | T15: =2783410+2783410 -> 5566820 | AI15: 2783410
A16: 409-5243 INSTITUTO TECNOLOGICO | C16: 2025 | D16: 13810 | I16: ccess point y switch Edificio de Ingenieria UCT (exTEC) | J16: 85398978 | L16: =J16-K16 -> 85398978 | O16: M.Zurita | Z16: 85398978
C17: 2025 | D17: 13310 | I17: Cortinas Cabañas Curacautín | J17: 4760000 | K17: =4760000*0.3 -> 1428000 | L17: =J17-K17 -> 3332000 | O17: F.Anselme | P17: =J17-K17-(SUM(Q17:BR17)) -> 0 | T17: 3332000
C18: 2025 | D18: 10880 | I18: Calculo Casino CRC | J18: 2808400 | L18: =J18-K18 -> 2808400 | O18: J.Solis de Ovando | P18: =J18-K18-(SUM(Q18:BR18)) -> 0 | Z18: 2808400
C19: 2025 | D19: 10877 | I19: Proyecto sanitario, pavimentación y topografía casino | J19: 2380000 | L19: =J19-K19 -> 2380000 | O19: J.Solis de Ovando | P19: =J19-K19-(SUM(Q19:BR19)) -> 0 | Z19: 2380000
C20: 2025 | D20: 12560 | I20: Diseño proyecto sanitario edificio Pabellón Docente | J20: 1880200 | L20: =J20-K20 -> 1880200 | O20: C.Correa | P20: =J20-K20-(SUM(Q20:BR20)) -> 0 | AG20: 1880200
C21: 2025 | D21: 5283 | I21: COMPRAS DE ACCESOS POINT, INSTALACION DISPOSITIVOS WIFI, OBRA MENORES SALA DOCTORADO HATCHERY CJP04, MENCHACA LIRA CML01 Y CONSTRUCCION POSTERIOR EDIFICIO A CSF16 | J21: 2519730 | L21: =J21-K21 -> 2519730 | O21: M.Zurita | P21: =J21-K21-(SUM(Q21:BR21)) -> 2519730
C22: 2024 | D22: 7981 | I22: SERVICIO EVALUACION CERTIFICACION EDIFICIO SUSTENTABLE, HOSPITAL SIMULACION Y PABELLON DOCENTE | J22: 4219946 | K22: 2260686 | L22: =J22-K22 -> 1959260 | N22: B-Green | O22: C.Correa | P22: =J22-K22-(SUM(Q22:BR22)) -> 0 | AK22: 1959260

Sheet Casino CRC
H1: PROGRAMACION FINANCIERA CRC11
B2: 2025 | C2: 2026 | H2: OC 1426/2026 | K2: actualizado 29/04
A3: TOTAL | B3: =B5+B14+B25+B47+B56+B63 -> 0 | C3: =C5+C14+C25+C47+C56+C63 -> 910200912 | I3: PROYECTADO | L3: REAL
H4: MES | I4: %PARCIAL | J4: %ACUMULADO | K4: EP PARCIAL | L4: EP REAL | M4: EP ACUMULADO | N4: %PARCIAL | O4: %ACUMULADO
B5: =SUM(B7:B12) -> 0 | C5: =SUM(C7:C12) -> 905200912 | G5: EP 1 | H5: MARZO | I5: 0.17 | J5: 0.18 | K5: 144479558 | L5: 144479558 | M5: =L5 -> 144479558 | N5: =L5/$K$13 -> 0.16894224 | O5: =N5 -> 0.16894224
A6: Obras | B6: 2025 | C6: 2026 | D6: 2027 | G6: EP 2 | H6: ABRIL | I6: 0.09 | J6: =J5+I6 -> 0.27 | K6: 69931126 | L6: 69931126 | M6: =L6+M5 -> 214410684 | N6: =L6/$K$13 -> 0.081771576 | O6: =N6+O5 -> 0.25071382
A7: Traslado de instalaciones | G7: EP 3 | H7: MAYO | I7: 0.21 | J7: =J6+I7 -> 0.48 | K7: 167082324 | L7: 163704571 | M7: =L7+M6 -> 378115255 | N7: =L7/$K$13 -> 0.19142235 | O7: =N7+O6 -> 0.44213617
A8: Demolición/certificados | G8: EP 4 | H8: JUNIO | I8: 0.19 | J8: =J7+I8 -> 0.67 | K8: 155127189 | L8: 105947180 | M8: =L8+M7 -> 484062435 | N8: =L8/$K$13 -> 0.12388572 | O8: =N8+O7 -> 0.56602189
A9: Construcción | C9: =K13 -> 855200912 | G9: EP 5 | H9: JULIO | I9: 0.22 | J9: =J8+I9 -> 0.89 | K9: 178457507 | L9: 108851059 | M9: =L9+M8 -> 592913494 | N9: =L9/$K$13 -> 0.12728127 | O9: =N9+O8 -> 0.69330316
A10: AO | C10: 50000000 | G10: EP 6 | H10: AGOSTO | I10: 0.12 | J10: =J9+I10 -> 1.01 | K10: 97363163 | M10: =L10+M9 -> 592913494 | N10: =L10/$K$13 -> 0 | O10: =N10+O9 -> 0.69330316
A11: Exteriores | D11: 100000000 | H11: TOTAL CON IVA | I11: =SUM(I5:I10) -> 1 | K11: =SUM(K5:K10) -> 812440867 | L11: =SUM(L5:L10) -> 592913494
A12: Otras | H12: RETENCION 5% | K12: =K13*0.05 -> 42760046 | L12: =K11-L11 -> 219527373
H13: TOTAL OBRA | K13: 855200912 | L13: =L12+L11 -> 812440867
B14: =SUM(B16:B23) -> 0 | C14: =SUM(C16:C23) -> 5000000 | M14: =M10+K12 -> 6.3567354e+08 | R14: actualizado 06/07
A15: Habilitación | B15: 2025 | C15: 2026
A16: Muebles
A17: Señalética | C17: 5000000
A18: Empavonados
A19: Pizarrones
A20: TV y/o Proyector | D20: 5000000
A21: Cortinas
A22: Access point y switch
A23: Otras
B25: =SUM(B27:B45) -> 0 | C25: =SUM(C27:C45) -> 0
A26: Especialidades | B26: 2025 | C26: 2026
A27: Arquitectura
A28: Estructura
A29: Mec. Suelos
A30: Topografía
A31: Eléctrico
A32: Incendio
A33: CCTV
A34: Control de acceso
A35: Fibra Óptica
A36: Sanitario
A37: Clima
A38: Pavimentación y ALL
... A45: Otras
B47: =SUM(B49:B54) -> 0 | C47: =SUM(C49:C54) -> 0
A48: Permiso | B48: 2025 | C48: 2026
...

Sheet Ingeniería
B2: 2022 | C2: 2023 | D2: 2024 | E2: 2025 | F2: 2026
A3: TOTAL | B3: =B5+B14+B25+B47+B56+B63 -> 1387792 | C3: =C5+C14+C25+C47+C56+C63 -> 73805375 | D3: =D5+D14+D25+D47+D56+D63 -> 1607650599 | E3: =E5+E14+E25+E47+E56+E63 -> 2991895909 | F3: =F5+F14+F25+F47+F56+F63 -> 1561941445 | H3: OC 8022/2024
H4: EP N° | I4: FECHA | J4: PROYECTADO | N4: REAL | O4: OBSERVACION
B5: =SUM(B7:B12) -> 0 | C5: =SUM(C7:C12) -> 44730910 | D5: =SUM(D7:D12) -> 1341967351 | E5: =SUM(E7:E12) -> 2922398707 | F5: =SUM(F7:F12) -> 1281182758 | J5: PARCIAL ($) | K5: ACUMULADO ($) | L5: PARCIAL (%) | M5: ACUMULADO (%)
A6: Obras | B6: 2022 | C6: 2023 | D6: 2024 | E6: 2025 | F6: 2026 | H6: 0 | I6: 45893 | J6: 200000000 | K6: =J6 -> 200000000 | L6: =J6/$J$26 -> 0.045368964 | M6: =K6/$J$26 -> 0.045368964 | N6: 200000000 | O6: Anticipo
A7: Traslado de instalaciones | H7: 1 | I7: 45893 | J7: 214576722 | K7: =J7+K6 -> 414576722 | L7: =J7/$J$26 -> 0.048675618 | M7: =K7/$J$26 -> 0.094044583 | N7: 214576722 | O7: PAGADO
A8: Demolición/certificados | C8: 41531000 | D8: =535500+8827420 -> 9362920 | H8: 2 | I8: 45924 | J8: 451540786 | K8: =J8+K7 -> 866117508 | L8: =J8/$J$26 -> 0.10242969 | M8: =K8/$J$26 -> 0.19647427 | N8: 451540786 | O8: PAGADO
A9: Construcción | D9: 1332604431 | E9: 2470313188 | F9: =J23+J24+J25 -> 574491551 | H9: 3 | I9: 45954 | J9: 242312734 | K9: =J9+K8 -> 1108430242 | L9: =J9/$J$26 -> 0.054967389 | M9: =K9/$J$26 -> 0.25144166 | N9: 242312734 | O9: PAGADO
A10: AO | E10: =J36 -> 452085519 | F10: =J46 -> 646691207 | H10: 4 | I10: 45985 | J10: 224174189 | K10: =J10+K9 -> 1332604431 | L10: =J10/$J$26 -> 0.050852754 | M10: =K10/$J$26 -> 0.30229442 | N10: 224174189 | O10: PAGADO 2024
A11: Exteriores | H11: 5 | I11: 46015 | J11: 155623352 | K11: =J11+K10 -> 1488227783 | L11: =J11/$J$26 -> 0.035302352 | M11: =K11/$J$26 -> 0.33759677 | N11: 155623352 | O11: PAGADO
A12: Otras | C12: 3199910 | F12: 60000000 | H12: 6 | I12: 45682 | J12: 252294712 | K12: =J12+K11 -> 1740522495 | L12: =J12/$J$26 -> 0.057231749 | M12: =K12/$J$26 -> 0.39482852 | N12: 252294712 | O12: PAGADO
H13: 7 | I13: 45719 | J13: 201102519 | K13: =J13+K12 -> 1941625014 | L13: =J13/$J$26 -> 0.045619065 | M13: =K13/$J$26 -> 0.44044758 | N13: 201102519 | O13: PAGADO
B14: =SUM(B16:B23) -> 0 | C14: =SUM(C16:C23) -> 0 | D14: =SUM(D16:D23) -> 98018000 | E14: =SUM(E16:E23) -> 0 | F14: =SUM(F16:F23) -> 175000000 | H14: 8 | I14: 45748 | J14: 155455601 | K14: =J14+K13 -> 2097080615 | L14: =J14/$J$26 -> 0.035264298 | M14: =K14/$J$26 -> 0.47571188 | N14: 155455601 | O14: PAGADO
A15: Habilitación | B15: 2022 | C15: 2023 | D15: 2024 | E15: 2025 | F15: 2026 | H15: 9 | I15: 45802 | J15: 218152853 | K15: =J15+K14 -> 2315233468 | L15: =J15/$J$26 -> 0.049486845 | M15: =K15/$J$26 -> 0.52519872 | N15: 218152853 | O15: PAGADO
A16: Muebles | D16: 98018000 | F16: 50000000 | H16: 10 | I16: 45833 | J16: 324983774 | K16: =J16+K15 -> 2640217242 | L16: =J16/$J$26 -> 0.073720886 | M16: =K16/$J$26 -> 0.59891961 | N16: 324983774 | O16: PAGADO
